<?xml version="1.0"?>
<robot name="rover" xmlns:xacro="http://www.ros.org/wiki/xacro" >

  <xacro:property name="wheel_radius" value="0.04"/>
  <xacro:property name="wheel_length" value="0.05"/>
  
  <xacro:macro name="wheel" params="name">
    <link name="${name}">
      <inertial>
        <mass value="0.1"/>
        <inertia ixx="1e-3" ixy="0.0" ixz="0.0" iyy="1e-3" iyz="0.0" izz="1e-3"/>
      </inertial>
      <visual>
        <geometry>
          <cylinder radius="${wheel_radius}" length="${wheel_length}"/>
	  <material name="black"/>
        </geometry>
      </visual>
      <collision>
        <origin rpy="0 0 0" xyz="0 0 0"/>
        <geometry>
          <cylinder radius="0.09" length="0.09"/>
        </geometry>
      </collision>
    </link>
  </xacro:macro>
  
  <xacro:macro name="chassis_link" params="name size">
    <link name="${name}">
      <inertial>
        <mass value="0.25"/>
        <inertia ixx="0.000486" ixy="0.0" ixz="0.0" iyy="0.000486" iyz="0.0" izz="0.000486"/>
      </inertial>
      <visual>
        <geometry>
          <box size="${size}"/>
          <material name="black"/>
        </geometry>
      </visual>
      <collision>
        <origin rpy="0 0 0" xyz="0 0 0"/>
        <geometry>
          <box size="${size}"/>
        </geometry>
      </collision>
    </link>
  </xacro:macro>   
  
  <xacro:macro name="static_joint" params="name parent child" >
    <joint name="${name}" type="fixed">
      <parent link="${parent}"/>
      <child link="${child}"/>
      <origin xyz="0 0 0" rpy="0 0 0"/>
    </joint>
  </xacro:macro>

  <xacro:macro name="wheel_joint" params="name parent child xyz ">
    <joint name="${name}" type="continuous">
      <axis xyz="0 0 1" />
      <parent link="${parent}" />
      <child link="${child}" />
      <origin xyz="${xyz}" rpy="1.570796 0 0"/>
    </joint>
  </xacro:macro>

</robot>
